Workbook

Sheet Fluxos Monetários
A1: (1) a matriz de fluxos em valores monetários Z, com os setores de valor adicionado e a demanda final;
A3: Valores correntes em 1 000 000 R$ | D3: S01 | E3: S02 | F3: S03 | G3: S04 | H3: S05 | I3: S06 | J3: S07 | K3: S08 | L3: S09 | M3: S10 | N3: S11 | O3: S12 | P3: S13 | Q3: S14 | R3: S15 | S3: S16 | T3: S17 | U3: S18 | V3: S19 | W3: S20 | X3: S21 | Y3: S22 | Z3: S23 | AA3: S24 | AB3: S25 | AC3: S26 | AD3: S27 | AE3: S28 | AF3: S29 | AG3: S30 | AH3: S31 | AI3: S32 | AJ3: S33 | AK3: S34 | AL3: S35 | AM3: S36 | AN3: S37 | AO3: S38 | AP3: S39 | AQ3: S40 | AR3: S41 | AS3: S42 | AT3: S43 | AU3: S44 | AV3: S45 | AW3: S46 | AX3: S47 | AY3: S48 | AZ3: S49 | BA3: S50 | BB3: S51 | BC3: S52 | BD3: S53 | BE3: S54 | BF3: S55 | BG3: S56 | BH3: S57 | BI3: S58 | BJ3: S59 | BK3: S60 | BL3: S61 | BM3: S62 | BN3: S63 | BO3: S64 | BP3: S65 | BQ3: S66 | BR3: S67 | BS3: S68 | BT3: S69 | BU3: S70 | BV3: S71 | BW3: S72 | BX3: S73
A4: Matriz de usos setor x setor | D4: Agricultura, inclusive o apoio à agricultura e a pós-colheita | E4: Pecuária, inclusive o apoio à pecuária | F4: Produção florestal; pesca e aquicultura | G4: Extração de carvão mineral e de minerais não-metálicos | H4: Extração de petróleo e gás, inclusive as atividades de apoio | I4: Extração de minério de ferro, inclusive beneficiamentos e a aglomeração | J4: Extração de minerais metálicos não-ferrosos, inclusive beneficiamentos | K4: Abate e produtos de carne, inclusive os produtos do laticínio e da pesca | L4: Fabricação e refino de açúcar | M4: Outros produtos alimentares | N4: Fabricação de bebidas | O4: Fabricação de produtos do fumo | P4: Fabricação de produtos têxteis | Q4: Confecção de artefatos do vestuário e acessórios | R4: Fabricação de calçados e de artefatos de couro | S4: Fabricação de produtos da madeira | T4: Fabricação de celulose, papel e produtos de papel | U4: Impressão e reprodução de gravações | V4: Derivados de petróleo | W4: Biodiesel | X4: Coquerias | Y4: Fabricação de biocombustíveis | Z4: Fabricação de químicos orgânicos e inorgânicos, resinas e elastômeros | AA4: Fabricação de defensivos, desinfestantes, tintas e químicos diversos | AB4: Fabricação de produtos de limpeza, cosméticos/perfumaria e higiene pessoal | AC4: Fabricação de produtos farmoquímicos e farmacêuticos | AD4: Fabricação de produtos de borracha e de material plástico | AE4: Fabricação de produtos de minerais não-metálicos | AF4: Produção de ferro-gusa/ferroligas, siderurgia e tubos de aço sem costura | AG4: Metalurgia de metais não-ferosos e a fundição de metais | AH4: Fabricação de produtos de metal, exceto máquinas e equipamentos | AI4: Fabricação de equipamentos de informática, produtos eletrônicos e ópticos | AJ4: Fabricação de máquinas e equipamentos elétricos | AK4: Fabricação de máquinas e equipamentos mecânicos | AL4: Fabricação de automóveis, caminhões e ônibus, exceto peças | AM4: Fabricação de peças e acessórios para veículos automotores | AN4: Fabricação de outros equipamentos de transporte, exceto veículos automotores | AO4: Fabricação de móveis e de produtos de indústrias diversas | AP4: Manutenção, reparação e instalação de máquinas e equipamentos | AQ4: Geração centralizada de energia elétrica | AR4: Geração distribuída de energia elétrica | AS4: Transmissão | AT4: Gás Natural | AU4: Água, esgoto e gestão de resíduos | AV4: Construção | AW4: Comércio e reparação de veículos automotores e motocicletas | AX4: Comércio por atacado e a varejo, exceto veículos automotores | AY4: Transporte terrestre | AZ4: Transporte aquaviário | BA4: Transporte aéreo | BB4: Armazenamento, atividades auxiliares dos transportes e correio | BC4: Alojamento | BD4: Alimentação | BE4: Edição e edição integrada à impressão | BF4: Atividades de televisão, rádio, cinema e gravação/edição de som e imagem | BG4: Telecomunicações | BH4: Desenvolvimento de sistemas e outros serviços de informação | BI4: Intermediação financeira, seguros e previdência complementar | BJ4: Atividades imobiliárias | BK4: Atividades jurídicas, contábeis, consultoria e sedes de empresas | BL4: Serviços de arquitetura, engenharia, testes/análises técnicas e P & D | BM4: Outras atividades profissionais, científicas e técnicas | BN4: Aluguéis não-imobiliários e gestão de ativos de propriedade intelectual | BO4: Outras atividades administrativas e serviços complementares | BP4: Atividades de vigilância, segurança e investigação | BQ4: Administração pública, defesa e seguridade social | BR4: Educação pública | BS4: Educação privada | BT4: Saúde pública | BU4: Saúde privada | BV4: Atividades artísticas, criativas e de espetáculos | BW4: Organizações associativas e outros serviços pessoais | BX4: Serviços domésticos | BY4: Consumo Intermediário total | BZ4: Exportação de bens e serviços | CA4: Consumo do governo | CB4: Consumo das ISFLSF | CC4: Consumo das famílias | CD4: Formação bruta de capital fixo | CE4: Variação de estoque | CF4: Demanda final | CG4: Demanda total | CI4: Proporção Demanda Final / Demanda total
B5: Número identificador | C5: 0 | D5: 1 | E5: 2 | F5: 3 | G5: 4 | H5: 5 | I5: 6 | J5: 7 | K5: 8 | L5: 9 | M5: 10 | N5: 11 | O5: 12 | P5: 13 | Q5: 14 | R5: 15 | S5: 16 | T5: 17 | U5: 18 | V5: 19 | W5: 20 | X5: 21 | Y5: 22 | Z5: 23 | AA5: 24 | AB5: 25 | AC5: 26 | AD5: 27 | AE5: 28 | AF5: 29 | AG5: 30 | AH5: 31 | AI5: 32 | AJ5: 33 | AK5: 34 | AL5: 35 | AM5: 36 | AN5: 37 | AO5: 38 | AP5: 39 | AQ5: 40 | AR5: 41 | AS5: 42 | AT5: 43 | AU5: 44 | AV5: 45 | AW5: 46 | AX5: 47 | AY5: 48 | AZ5: 49 | BA5: 50 | BB5: 51 | BC5: 52 | BD5: 53 | BE5: 54 | BF5: 55 | BG5: 56 | BH5: 57 | BI5: 58 | BJ5: 59 | BK5: 60 | BL5: 61 | BM5: 62 | BN5: 63 | BO5: 64 | BP5: 65 | BQ5: 66 | BR5: 67 | BS5: 68 | BT5: 69 | BU5: 70 | BV5: 71 | BW5: 72 | BX5: 73 | BY5: 74 | BZ5: 75 | CA5: 76 | CB5: 77 | CC5: 78 | CD5: 79 | CE5: 80 | CF5: 81 | CG5: 82
A6: S01 | B6: Agricultura, inclusive o apoio à agricultura e a pós-colheita | C6: 1 | D6: 8170.3586 | E6: 5290.2246 | F6: 156.75542 | G6: 1.8265937 | H6: 9.8692679 | I6: 1.1434984 | J6: 1.7841451 | K6: 7264.3074 | L6: 28021.78 | M6: 76458.432 | N6: 2089.3011 | O6: 4889.0335 | P6: 5526.2619 | Q6: 518.70182 | R6: 6.6028531 | S6: 90.994169 | T6: 172.72948 | U6: 0.25638423 | V6: 8.6760449 | W6: 0.051985351 | X6: 0.041880586 | Y6: 22484.79 | Z6: 15.129223 | AA6: 18.049511 | AB6: 2.2091675 | AC6: 13.484794 | AD6: 38.146982 | AE6: 14.418004 | AF6: 42.241869 | AG6: 26.216602 | AH6: 2.7665426 | AI6: 0.27528051 | AJ6: 0.30007581 | AK6: 0.76078595 | AL6: 0.62121565 | AM6: 0.40229091 | AN6: 0.52416479 | AO6: 10.45024 | AP6: 0.065167124 | AQ6: 0.47598929 | AR6: 0.077753282 | AS6: 0.055707325 | AT6: 0.062671933 | AU6: 28.709259 | AV6: 402.52785 | AW6: 2.6558165 | AX6: 12090.688 | AY6: 0.96387781 | AZ6: 0.028456625 | BA6: 0.29297865 | BB6: 12.456639 | BC6: 277.13534 | BD6: 4385.9634 | BE6: 0.088943908 | BF6: 0.61952657 | BG6: 44.855835 | BH6: 2.1532612 | BI6: 14.762971 | BJ6: 20.40651 | BK6: 7.4743084 | BL6: 12.024632 | BM6: 0.80278958 | BN6: 0.68757086 | BO6: 133.6114 | BP6: 0.22205855 | BQ6: 947.57032 | BR6: 357.35736 | BS6: 43.808221 | BT6: 354.48805 | BU6: 180.63426 | BV6: 2.8571215 | BW6: 249.91177 | BX6: 0 | BY6: 180926.42 | BZ6: 150718.72 | CA6: 48.304678 | CB6: 0 | CC6: 71191.699 | CD6: 3188.2578 | CE6: -8036.3973 | CF6: 217110.58 | CG6: 398037 | CI6: =CF6/CG6 -> 0.54545327
A7: S02 | B7: Pecuária, inclusive o apoio à pecuária | C7: 2 | D7: 1004.9599 | E7: 6106.8111 | F7: 183.36264 | G7: 3.7251917 | H7: 22.939 | I7: 1.9494384 | J7: 3.2441343 | K7: 84046.279 | L7: 152.99908 | M7: 4376.6755 | N7: 64.457872 | O7: 192.81143 | P7: 250.2414 | Q7: 190.38282 | R7: 6.6377087 | S7: 143.03866 | T7: 239.09947 | U7: 0.46679488 | V7: 0.72657442 | W7: 0.018633166 | X7: 0.0001190597 | Y7: 178.77565 | Z7: 46.126672 | AA7: 7.8961205 | AB7: 5.0532195 | AC7: 5.4165196 | AD7: 52.888428 | AE7: 56.619524 | AF7: 70.6231 | AG7: 49.444454 | AH7: 2.5281526 | AI7: 0.71683903 | AJ7: 0.95724033 | AK7: 1.7317397 | AL7: 1.242744 | AM7: 0.99247143 | AN7: 0.87514563 | AO7: 7.2734053 | AP7: 0.23085892 | AQ7: 0.79136222 | AR7: 0.12926974 | AS7: 0.092616943 | AT7: 0.16790002 | AU7: 5.6993907 | AV7: 751.8631 | AW7: 3.5113748 | AX7: 386.78199 | AY7: 1.0736839 | AZ7: 0.037829304 | BA7: 0.34145151 | BB7: 22.136468 | BC7: 331.24359 | BD7: 1919.459 | BE7: 0.21618546 | BF7: 1.1913409 | BG7: 80.686603 | BH7: 4.2899018 | BI7: 25.488379 | BJ7: 38.429739 | BK7: 6.829628 | BL7: 14.52577 | BM7: 6.4682792 | BN7: 1.1312263 | BO7: 36.689298 | BP7: 0.34850966 | BQ7: 301.70844 | BR7: 120.20425 | BS7: 17.204426 | BT7: 110.89112 | BU7: 110.42372 | BV7: 3.3228892 | BW7: 37.971527 | BX7: 0 | BY7: 101821.57 | BZ7: 7635.5157 | CA7: 3.1875319 | CB7: 0 | CC7: 27053.775 | CD7: 16625.08 | CE7: -1180.1272 | CF7: 50137.431 | CG7: 151959 | CI7: =CF7/CG7 -> 0.32994052
A8: S03 | B8: Produção florestal; pesca e aquicultura | C8: 3 | D8: 1414.9162 | E8: 1437.2819 | F8: 2063.4117 | G8: 1.7907537 | H8: 1.8236877 | I8: 0.17010573 | J8: 0.24112751 | K8: 1830.067 | L8: 0.62916373 | M8: 261.16769 | N8: 13.874288 | O8: 13.085165 | P8: 25.024372 | Q8: 8.2471144 | R8: 6.78895 | S8: 1995.4595 | T8: 3242.7461 | U8: 0.035396002 | V8: 0.056630047 | W8: 0.0014522904 | X8: 9.2796503e-06 | Y8: 3.6633906 | Z8: 162.13204 | AA8: 2.8177035 | AB8: 0.084317617 | AC8: 0.12671282 | AD8: 713.86171 | AE8: 59.563969 | AF8: 910.44283 | AG8: 3.7053405 | AH8: 5.5140517 | AI8: 0.069501986 | AJ8: 0.088522362 | AK8: 0.17941951 | AL8: 0.11471484 | AM8: 0.093657764 | AN8: 0.076952408 | AO8: 2.773387 | AP8: 0.02522399 | AQ8: 0.094589682 | AR8: 0.015451311 | AS8: 0.011070287 | AT8: 0.019459657 | AU8: 0.4257136 | AV8: 759.42361 | AW8: 0.27333371 | AX8: 161.92523 | AY8: 0.099740228 | AZ8: 0.0030144069 | BA8: 0.027363157 | BB8: 1.6585272 | BC8: 42.674553 | BD8: 549.53668 | BE8: 0.021951251 | BF8: 0.10959413 | BG8: 5.9766224 | BH8: 0.36575555 | BI8: 1.9402982 | BJ8: 2.9162219 | BK8: 0.52073673 | BL8: 3.7816158 | BM8: 0.083967239 | BN8: 0.095237422 | BO8: 2.6303824 | BP8: 0.029566698 | BQ8: 91.342914 | BR8: 66.866054 | BS8: 8.8889308 | BT8: 63.403735 | BU8: 19.813852 | BV8: 0.24397311 | BW8: 2.9434756 | BX8: 0 | BY8: 15970.315 | BZ8: 3068.1586 | CA8: 2.4427056 | CB8: 0 | CC8: 17611.77 | CD8: 1054.003 | CE8: 163.3106 | CF8: 21899.685 | CG8: 37870 | CI8: =CF8/CG8 -> 0.57828585
A9: S04 | B9: Extração de carvão mineral e de minerais não-metálicos | C9: 4 | D9: 154.57131 | E9: 418.65628 | F9: 13.284636 | G9: 255.38746 | H9: 731.23872 | I9: 0.30874708 | J9: 1.3587158 | K9: 53.244166 | L9: 8.1587147 | M9: 279.65589 | N9: 16.421368 | O9: 0.065622521 | P9: 0.97438319 | Q9: 0.29823967 | R9: 0.94713613 | S9: 0.22325809 | T9: 18.581952 | U9: 0.14003746 | V9: 6.1948655 | W9: 0.1589928 | X9: 0.0058538919 | Y9: 219.10581 | Z9: 2854.8663 | AA9: 68.702101 | AB9: 8.0050703 | AC9: 1.8960083 | AD9: 6.7281211 | AE9: 4463.2487 | AF9: 1496.018 | AG9: 337.50822 | AH9: 3.5700793 | AI9: 0.34796092 | AJ9: 35.919486 | AK9: 2.5200509 | AL9: 18.623404 | AM9: 34.401273 | AN9: 1.7813222 | AO9: 31.983519 | AP9: 2.7992514 | AQ9: 235.19416 | AR9: 5.7714331 | AS9: 1.184596 | AT9: 1.2563515 | AU9: 356.51608 | AV9: 5769.238 | AW9: 2.9175716 | AX9: 79.436083 | AY9: 0.65802409 | AZ9: 0.02811291 | BA9: 0.057457623 | BB9: 4.3639196 | BC9: 2.4382302 | BD9: 15.584106 | BE9: 0.087448574 | BF9: 0.1645093 | BG9: 0.76492018 | BH9: 0.61648428 | BI9: 1.6296091 | BJ9: 369.75982 | BK9: 1.5956916 | BL9: 1.1474393 | BM9: 0.42774142 | BN9: 0.35090323 | BO9: 2.106388 | BP9: 0.086702237 | BQ9: 71.223802 | BR9: 16.960069 | BS9: 1.5619518 | BT9: 6.8222989 | BU9: 5.5002185 | BV9: 1.1191405 | BW9: 4.310632 | BX9: 0 | BY9: 18508.781 | BZ9: 1808.1263 | CA9: 0.074826886 | CB9: 0 | CC9: 199.54565 | CD9: 9.7663346 | CE9: -515.2941 | CF9: 1502.2191 | CG9: 20011 | CI9: =CF9/CG9 -> 0.075069665
A10: S05 | B10: Extração de petróleo e gás, inclusive as atividades de apoio | C10: 5 | D10: 21.840529 | E10: 15.400401 | F10: 0.88883243 | G10: 2.8557716 | H10: 6630.1612 | I10: 276.15336 | J10: 28.805251 | K10: 63.705839 | L10: 0.44529788 | M10: 591.27168 | N10: 106.02011 | O10: 0.12079151 | P10: 91.397968 | Q10: 0.98598288 | R10: 1.5852201 | S10: 39.944558 | T10: 541.2167 | U10: 0.14283782 | V10: 106597.07 | W10: 2746.8599 | X10: 590.10146 | Y10: 1.2543756 | Z10: 1369.8245 | AA10: 67.887327 | AB10: 24.388558 | AC10: 28.616612 | AD10: 80.815094 | AE10: 444.90473 | AF10: 358.13112 | AG10: 243.1048 | AH10: 282.1276 | AI10: 1.128992 | AJ10: 26.624933 | AK10: 19.396171 | AL10: 62.055893 | AM10: 126.58879 | AN10: 1.6722904 | AO10: 2.9946627 | AP10: 6.2288933 | AQ10: 3962.6267 | AR10: 1.0026425 | AS10: 0.71835594 | AT10: 5204.7213 | AU10: 522.87686 | AV10: 571.58375 | AW10: 9.6259108 | AX10: 157.08909 | AY10: 72.420509 | AZ10: 0.79119726 | BA10: 0.27180433 | BB10: 47.629023 | BC10: 3.4384093 | BD10: 49.277023 | BE10: 0.46020694 | BF10: 1.2321138 | BG10: 87.263751 | BH10: 4.8051068 | BI10: 13.428733 | BJ10: 6.8459631 | BK10: 13.309644 | BL10: 55.849417 | BM10: 3.1144653 | BN10: 5.7667873 | BO10: 9.2018492 | BP10: 0.72124886 | BQ10: 1045.7362 | BR10: 8.0402548 | BS10: 12.284845 | BT10: 1.4955079 | BU10: 7.5123371 | BV10: 9.5743714 | BW10: 21.701482 | BX10: 0 | BY10: 133407.14 | BZ10: 92727.09 | CA10: 0 | CB10: 0 | CC10: 602.27835 | CD10: 11369.449 | CE10: -12167.956 | CF10: 92530.862 | CG10: 225938 | CI10: =CF10/CG10 -> 0.40954095
A11: S06 | B11: Extração de minério de ferro, inclusive beneficiamentos e a aglomeração | C11: 6 | D11: 0.13674266 | E11: 0.077076579 | F11: 0.0079907095 | G11: 0.02196498 | H11: 2.3512303 | I11: 1793.5447 | J11: 45.052166 | K11: 0.48557035 | L11: 0.032457224 | M11: 0.34478482 | N11: 0.27770406 | O11: 0.063359672 | P11: 0.043394837 | Q11: 0.095809719 | R11: 0.10896933 | S11: 0.074421837 | T11: 0.14841067 | U11: 0.014610975 | V11: 0.14103175 | W11: 0.0036167913 | X11: 2.3110087e-05 | Y11: 0.017588449 | Z11: 0.34414227 | AA11: 0.11931618 | AB11: 0.21383963 | AC11: 0.70292247 | AD11: 0.20161083 | AE11: 106.29352 | AF11: 16914.009 | AG11: 123.08645 | AH11: 0.096515193 | AI11: 0.2311134 | AJ11: 0.55081086 | AK11: 4.5165857 | AL11: 1.1407709 | AM11: 0.66480908 | AN11: 0.23246828 | AO11: 0.11436779 | AP11: 2.6358292 | AQ11: 0.28979805 | AR11: 0.047338775 | AS11: 0.033916466 | AT11: 0.019881708 | AU11: 0.072340698 | AV11: 1.2898289 | AW11: 0.20090651 | AX11: 1.8876588 | AY11: 0.11844738 | AZ11: 0.04249387 | BA11: 0.0099650457 | BB11: 0.14510725 | BC11: 0.043813445 | BD11: 0.31459912 | BE11: 0.020385269 | BF11: 0.020853743 | BG11: 0.29065394 | BH11: 0.36060677 | BI11: 0.19109174 | BJ11: 0.07465067 | BK11: 0.16290206 | BL11: 6.5571966 | BM11: 0.053040758 | BN11: 0.12392835 | BO11: 0.64194197 | BP11: 0.010178673 | BQ11: 0.14299228 | BR11: 0.052338503 | BS11: 0.14785893 | BT11: 0.091322143 | BU11: 0.22754425 | BV11: 0.11034237 | BW11: 0.13327856 | BX11: 0 | BY11: 19012.127 | BZ11: 65510.697 | CA11: 0.014070934 | CB11: 0 | CC11: 7.116125 | CD11: 145.98411 | CE11: 7650.0619 | CF11: 73313.873 | CG11: 92326 | CI11: =CF11/CG11 -> 0.79407613
A12: S07 | B12: Extração de minerais metálicos não-ferrosos, inclusive beneficiamentos | C12: 7 | D12: 4.6695015 | E12: 2.628304 | F12: 0.12435658 | G12: 1.2402923 | H12: 68.177003 | I12: 10.656378 | J12: 810.56588 | K12: 6.0089169 | L12: 0.15093813 | M12: 12.972218 | N12: 1.4659626 | O12: 0.0030025647 | P12: 0.16470019 | Q12: 0.037493815 | R12: 0.28587826 | S12: 0.12078567 | T12: 5.8959539 | U12: 3.4978879 | V12: 0.045892973 | W12: 0.0011822536 | X12: 0.00021491581 | Y12: 0.99308581 | Z12: 30.317773 | AA12: 5.272019 | AB12: 1.7076522 | AC12: 0.54015883 | AD12: 7.8003983 | AE12: 52.370365 | AF12: 1602.2277 | AG12: 5411.8108 | AH12: 31.658929 | AI12: 2.4799909 | AJ12: 79.4302 | AK12: 12.403471 | AL12: 8.4362246 | AM12: 49.252453 | AN12: 12.92217 | AO12: 30.016131 | AP12: 5.5688269 | AQ12: 0.38191835 | AR12: 0.06238671 | AS12: 0.044697749 | AT12: 0.002747953 | AU12: 3.6386314 | AV12: 59.821666 | AW12: 0.56351331 | AX12: 3.5850876 | AY12: 0.16152433 | AZ12: 0 | BA12: 0.0036377033 | BB12: 0.073311621 | BC12: 0.0046298042 | BD12: 0.25629273 | BE12: 0.00037532059 | BF12: 0 | BG12: 0.012010259 | BH12: 0.01938281 | BI12: 0.015203035 | BJ12: 2.0032489 | BK12: 0.23876561 | BL12: 0.70972307 | BM12: 0.0016222907 | BN12: 0.0054421485 | BO12: 0.26001967 | BP12: 0 | BQ12: 0.51230206 | BR12: 0.19266821 | BS12: 0.00018766029 | BT12: 0.41110175 | BU12: 0.71872299 | BV12: 0 | BW12: 0.38814583 | BX12: 0 | BY12: 8348.0101 | BZ12: 11140.001 | CA12: 0 | CB12: 0 | CC12: 7.4490404 | CD12: 8.4306387 | CE12: -1230.8903 | CF12: 9924.9899 | CG12: 18273 | CI12: =CF12/CG12 -> 0.54315054
A13: S08 | B13: Abate e produtos de carne, inclusive os produtos do laticínio e da pesca | C13: 8 | D13: 73.15487 | E13: 2090.4666 | F13: 38.303224 | G13: 9.9476144 | H13: 19.441015 | I13: 17.034337 | J13: 3.2840564 | K13: 22154.159 | L13: 1.0823479 | M13: 2486.5336 | N13: 47.126808 | O13: 2.4639672 | P13: 7.0604126 | Q13: 8.6616937 | R13: 1473.7109 | S13: 5.5399254 | T13: 15.727026 | U13: 3.1952587 | V13: 23.045817 | W13: 0.59120438 | X13: 0.011154334 | Y13: 737.52755 | Z13: 29.649497 | AA13: 44.063117 | AB13: 1728.7212 | AC13: 13.395568 | AD13: 28.418666 | AE13: 9.9546155 | AF13: 10.274331 | AG13: 5.788068 | AH13: 65.983484 | AI13: 13.052513 | AJ13: 11.427341 | AK13: 65.885116 | AL13: 13.947594 | AM13: 8.0334682 | AN13: 3.9970415 | AO13: 12.233521 | AP13: 40.666301 | AQ13: 4.9078319 | AR13: 0.80169879 | AS13: 0.57438727 | AT13: 0.39508868 | AU13: 3.2880463 | AV13: 58.979781 | AW13: 7.2079814 | AX13: 448.87841 | AY13: 13.177598 | AZ13: 0.87761198 | BA13: 1.2127732 | BB13: 4.6743079 | BC13: 445.42571 | BD13: 17469.215 | BE13: 1.6282579 | BF13: 1.6628426 | BG13: 6.3279886 | BH13: 4.661158 | BI13: 8.4847063 | BJ13: 4.2251629 | BK13: 7.7048874 | BL13: 6.6234746 | BM13: 5.7445294 | BN13: 2.4002707 | BO13: 15.891834 | BP13: 0.73876873 | BQ13: 2176.6448 | BR13: 1294.0752 | BS13: 207.92015 | BT13: 1280.2889 | BU13: 750.19255 | BV13: 7.872699 | BW13: 194.08998 | BX13: 0 | BY13: 55760.354 | BZ13: 46170.634 | CA13: 72.403107 | CB13: 0 | CC13: 189902.01 | CD13: 408.57985 | CE13: 92.022182 | CF13: 236645.65 | CG13: 292406 | CI13: =CF13/CG13 -> 0.80930503
A14: S09 | B14: Fabricação e refino de açúcar | C14: 9 | D14: 53.525246 | E14: 87.091629 | F14: 2.3933686 | G14: 1.6267936 | H14: 330.37378 | I14: 22.21335 | J14: 3.8758144 | K14: 291.48502 | L14: 755.07055 | M14: 3193.1451 | N14: 671.87757 | O14: 0.80970769 | P14: 2.0182717 | Q14: 2.6748804 | R14: 2.0719631 | S14: 14.517455 | T14: 5.707496 | U14: 0.69458071 | V14: 7507.7582 | W14: 38.065829 | X14: 37.884553 | Y14: 641.94531 | Z14: 141.83333 | AA14: 414.07002 | AB14: 612.65487 | AC14: 355.93829 | AD14: 4.1415098 | AE14: 3.0130159 | AF14: 3.8189358 | AG14: 2.182539 | AH14: 17.070744 | AI14: 4.3963944 | AJ14: 6.2673357 | AK14: 94.892959 | AL14: 16.375697 | AM14: 2.8484954 | AN14: 3.8857596 | AO14: 3.4125174 | AP14: 59.620441 | AQ14: 4.5778112 | AR14: 0.74778963 | AS14: 0.53576336 | AT14: 0.18604367 | AU14: 10.534485 | AV14: 172.49428 | AW14: 139.72003 | AX14: 273.44868 | AY14: 351.88253 | AZ14: 3.0478343 | BA14: 9.5131123 | BB14: 24.925262 | BC14: 7.1586323 | BD14: 795.99698 | BE14: 2.2736976 | BF14: 4.3632644 | BG14: 12.172919 | BH14: 17.104176 | BI14: 62.695757 | BJ14: 8.9417937 | BK14: 62.340633 | BL14: 49.822366 | BM14: 19.535258 | BN14: 47.389975 | BO14: 66.916953 | BP14: 31.905779 | BQ14: 347.6269 | BR14: 93.441802 | BS14: 10.050684 | BT14: 71.418105 | BU14: 65.577576 | BV14: 9.0821778 | BW14: 75.349417 | BX14: 0 | BY14: 18266.028 | BZ14: 16586.094 | CA14: 0.75832747 | CB14: 0 | CC14: 16804.06 | CD14: 332.2654 | CE14: -434.20561 | CF14: 33288.972 | CG14: 51555 | CI14: =CF14/CG14 -> 0.64569823
A15: S10 | B15: Outros produtos alimentares | C15: 10 | D15: 1901.0055 | E15: 13289.225 | F15: 896.41033 | G15: 153.2433 | H15: 190.88615 | I15: 51.948534 | J15: 15.388239 | K15: 23451.189 | L15: 23.73499 | M15: 28439.3 | N15: 2077.0625 | O15: 14.848455 | P15: 56.298103 | Q15: 48.649656 | R15: 64.823663 | S15: 57.154409 | T15: 656.92772 | U15: 23.74503 | V15: 2090.5259 | W15: 13.734147 | X15: 9.9100746 | Y15: 3052.5007 | Z15: 488.08572 | AA15: 802.79043 | AB15: 1071.7383 | AC15: 229.29723 | AD15: 175.308 | AE15: 93.455962 | AF15: 91.502096 | AG15: 40.730426 | AH15: 88.811443 | AI15: 75.800275 | AJ15: 60.469387 | AK15: 109.61639 | AL15: 56.823494 | AM15: 43.043403 | AN15: 18.514591 | AO15: 81.249431 | AP15: 72.461506 | AQ15: 32.640495 | AR15: 5.3318544 | AS15: 3.8200747 | AT15: 1.9974554 | AU15: 32.438763 | AV15: 362.30878 | AW15: 131.80172 | AX15: 3488.1786 | AY15: 177.61548 | AZ15: 2.5711517 | BA15: 31.863844 | BB15: 38.202178 | BC15: 243.18735 | BD15: 12354.485 | BE15: 10.176693 | BF15: 10.564222 | BG15: 46.146675 | BH15: 27.97588 | BI15: 179.04353 | BJ15: 39.398785 | BK15: 74.566393 | BL15: 36.341617 | BM15: 66.42593 | BN15: 23.287125 | BO15: 77.880838 | BP15: 12.251409 | BQ15: 1527.907 | BR15: 1168.2631 | BS15: 166.10331 | BT15: 1598.3147 | BU15: 711.43383 | BV15: 52.378456 | BW15: 738.0151 | BX15: 0 | BY15: 103651.13 | BZ15: 40248.49 | CA15: 79.511138 | CB15: 0 | CC15: 177717.31 | CD15: 617.39769 | CE15: 2629.1666 | CF15: 221291.87 | CG15: 324943 | CI15: =CF15/CG15 -> 0.68101751
A16: S11 | B16: Fabricação de bebidas | C16: 11 | D16: 14.73899 | E16: 9.3559629 | F16: 0.76997094 | G16: 5.2965241 | H16: 13.258631 | I16: 7.7752004 | J16: 1.7552234 | K16: 397.9374 | L16: 1.2398412 | M16: 99.164789 | N16: 6639.8139 | O16: 1.607351 | P16: 4.5283349 | Q16: 5.5452055 | R16: 4.3324331 | S16: 4.1709141 | T16: 8.1110653 | U16: 1.6440958 | V16: 62.724309 | W16: 0.63813413 | X16: 0.24728806 | Y16: 3.2332953 | Z16: 10.807878 | AA16: 13.785349 | AB16: 11.285939 | AC16: 8.407027 | AD16: 10.372939 | AE16: 5.7335931 | AF16: 10.690565 | AG16: 3.6727054 | AH16: 20.532547 | AI16: 9.8421771 | AJ16: 9.681718 | AK16: 31.591531 | AL16: 12.546867 | AM16: 8.0829596 | AN16: 5.4079929 | AO16: 8.3460781 | AP16: 19.980903 | AQ16: 8.2460964 | AR16: 1.3470073 | AS16: 0.96508049 | AT16: 0.45259475 | AU16: 3.0293874 | AV16: 69.490475 | AW16: 10.121867 | AX16: 107.19138 | AY16: 17.00447 | AZ16: 0.45098489 | BA16: 8.1017402 | BB16: 6.2954672 | BC16: 450.04095 | BD16: 26011.353 | BE16: 1.2831512 | BF16: 1.6703356 | BG16: 6.6399483 | BH16: 5.1156866 | BI16: 98.337038 | BJ16: 6.2222205 | BK16: 12.41899 | BL16: 3.020191 | BM16: 4.3590942 | BN16: 2.9262015 | BO16: 13.385941 | BP16: 1.1279803 | BQ16: 100.9831 | BR16: 69.203497 | BS16: 17.627628 | BT16: 72.575288 | BU16: 174.85303 | BV16: 28.677202 | BW16: 19.690719 | BX16: 0 | BY16: 34822.866 | BZ16: 2978.2515 | CA16: 1.7119308 | CB16: 0 | CC16: 40937.66 | CD16: 99.164106 | CE16: -295.65319 | CF16: 43721.134 | CG16: 78544 | CI16: =CF16/CG16 -> 0.55664512
A17: S12 | B17: Fabricação de produtos do fumo | C17: 12 | D17: 1.8863692 | E17: 0.9809415 | F17: 0.089514122 | G17: 0.088027857 | H17: 2.1983798 | I17: 2.4823702 | J17: 0.38449654 | K17: 3.1242665 | L17: 0.08724313 | M17: 3.0183844 | N17: 0.69678189 | O17: 304.40931 | P17: 0.50326689 | Q17: 0.6927617 | R17: 0.57329707 | S17: 0.29665773 | T17: 0.77841528 | U17: 0.1475926 | V17: 1.9269422 | W17: 0.04941687 | X17: 0.00031575728 | Y17: 0.17235201 | Z17: 1.1070472 | AA17: 0.63432236 | AB17: 0.4849366 | AC17: 0.79277348 | AD17: 0.99845903 | AE17: 0.6455419 | AF17: 0.71252419 | AG17: 0.61963993 | AH17: 0.72265568 | AI17: 1.1712195 | AJ17: 1.1271924 | AK17: 9.9519577 | AL17: 1.7055668 | AM17: 0.71215732 | AN17: 0.50240734 | AO17: 0.67606475 | AP17: 6.042271 | AQ17: 0.46340185 | AR17: 0.075697113 | AS17: 0.054234156 | AT17: 0.031969707 | AU17: 0.18846967 | AV17: 5.1648107 | AW17: 0.45008789 | AX17: 3.6160293 | AY17: 1.1145936 | AZ17: 0.10844203 | BA17: 0.10146145 | BB17: 0.28571454 | BC17: 0.1431338 | BD17: 2.3330807 | BE17: 0.14060472 | BF17: 0.12207898 | BG17: 0.53625142 | BH17: 0.43983917 | BI17: 0.45998094 | BJ17: 0.24562702 | BK17: 0.37100818 | BL17: 1.3352302 | BM17: 0.34056163 | BN17: 0.16603915 | BO17: 1.6680395 | BP17: 0.047183572 | BQ17: 0.73080867 | BR17: 0.48670412 | BS17: 0.26664794 | BT17: 0.6912563 | BU17: 1.7783447 | BV17: 0.16768687 | BW17: 0.52694909 | BX17: 0 | BY17: 377.84581 | BZ17: 6460.6451 | CA17: 0.19900321 | CB17: 0 | CC17: 7980.5129 | CD17: 100.82736 | CE17: 773.96982 | CF17: 15316.154 | CG17: 15694 | CI17: =CF17/CG17 -> 0.97592419
... A78: S73 | B78: Serviços domésticos | C78: 73 | D78: 0 | E78: 0 | F78: 0 | G78: 0 | H78: 0 | I78: 0 | J78: 0 | K78: 0 | L78: 0 | M78: 0 | N78: 0 | O78: 0 | P78: 0 | Q78: 0 | R78: 0 | S78: 0 | T78: 0 | U78: 0 | V78: 0 | W78: 0 | X78: 0 | Y78: 0 | Z78: 0 | AA78: 0 | AB78: 0 | AC78: 0 | AD78: 0 | AE78: 0 | AF78: 0 | AG78: 0 | AH78: 0 | AI78: 0 | AJ78: 0 | AK78: 0 | AL78: 0 | AM78: 0 | AN78: 0 | AO78: 0 | AP78: 0 | AQ78: 0 | AR78: 0 | AS78: 0 | AT78: 0 | AU78: 0 | AV78: 0 | AW78: 0 | AX78: 0 | AY78: 0 | AZ78: 0 | BA78: 0 | BB78: 0 | BC78: 0 | BD78: 0 | BE78: 0 | BF78: 0 | BG78: 0 | BH78: 0 | BI78: 0 | BJ78: 0 | BK78: 0 | BL78: 0 | BM78: 0 | BN78: 0 | BO78: 0 | BP78: 0 | BQ78: 0 | BR78: 0 | BS78: 0 | BT78: 0 | BU78: 0 | BV78: 0 | BW78: 0 | BX78: 0 | BY78: 0 | BZ78: 0 | CA78: 0 | CB78: 0 | CC78: 74451 | CD78: 0 | CE78: 0 | CF78: 74451 | CG78: 74451 | CI78: =CF78/CG78 -> 1
B79: Prod Nac | C79: 74 | D79: 149151.39 | E79: 68079.254 | F79: 8177.4548 | G79: 9360.8652 | H79: 86780.302 | I79: 38249.787 | J79: 8861.9731 | K79: 226295.97 | L79: 40680.402 | M79: 229159.4 | N79: 47291.889 | O79: 10510.046 | P79: 30369.291 | Q79: 29704.034 | R79: 22278.689 | S79: 17495.769 | T79: 62825.276 | U79: 8728.225 | V79: 287013.67 | W79: 6884.7092 | X79: 3133.1479 | Y79: 39806.995 | Z79: 93685.49 | AA79: 50165.759 | AB79: 29616.109 | AC79: 32534.935 | AD79: 67095.931 | AE79: 47995.653 | AF79: 90011.633 | AG79: 42241.063 | AH79: 55292.639 | AI79: 48924.359 | AJ79: 43882.672 | AK79: 69100.829 | AL79: 125399.05 | AM79: 57957.342 | AN79: 14198.782 | AO79: 34015.197 | AP79: 34232.729 | AQ79: 127681.24 | AR79: 18161.429 | AS79: 4642.9823 | AT79: 13663.351 | AU79: 25919.117 | AV79: 258586.87 | AW79: 61466.17 | AX79: 379634.9 | AY79: =SUM(AY6:AY78) -> 203094.51 | AZ79: 10000.749 | BA79: 22005.894 | BB79: 50075.886 | BC79: 11174.565 | BD79: 120776.23 | BE79: 7719.1866 | BF79: 22366.727 | BG79: 80996.904 | BH79: 45349.946 | BI79: 196028.97 | BJ79: 44529.805 | BK79: 62859.567 | BL79: 18857.747 | BM79: 59576.858 | BN79: 14344.205 | BO79: 71519.591 | BP79: 6663.1352 | BQ79: 207583.76 | BR79: 47100.065 | BS79: 34108.375 | BT79: 55184.158 | BU79: 109176.75 | BV79: 14856.013 | BW79: 67590.784 | BX79: 0 | BY79: 4840485.2 | BZ79: 1025056 | CA79: 1393480 | CB79: 102253 | CC79: 3769922 | CD79: 878944.83 | CE79: -131 | CF79: 7169524.8 | CG79: 12010010
B80: Importado | C80: 75 | D80: 24183.129 | E80: 5755.6609 | F80: 537.51612 | G80: 1556.2578 | H80: 27867.644 | I80: 5714.0844 | J80: 1597.9782 | K80: 6328.4894 | L80: 797.17685 | M80: 16720.175 | N80: 3497.4522 | O80: 722.70448 | P80: 5295.776 | Q80: 4427.6391 | R80: 2917.4641 | S80: 1608.7089 | T80: 9260.3347 | U80: 1398.3211 | V80: 55572.301 | W80: 1426.2976 | X80: 53.305845 | Y80: 1431.7307 | Z80: 48562.221 | AA80: 17822.444 | AB80: 6237.9026 | AC80: 5422.9335 | AD80: 17408.563 | AE80: 6069.3113 | AF80: 19877.812 | AG80: 11436.201 | AH80: 8465.1792 | AI80: 30697.93 | AJ80: 11191.577 | AK80: 15905.433 | AL80: 26596.214 | AM80: 12200.315 | AN80: 14472.288 | AO80: 4902.2705 | AP80: 13043.475 | AQ80: 9178.8369 | AR80: 1499.3714 | AS80: 1074.2436 | AT80: 1248.4881 | AU80: 3312.4579 | AV80: 25282.9 | AW80: 9933.6931 | AX80: 25771.75 | AY80: 14216.85 | AZ80: 1813.1869 | BA80: 6864.6108 | BB80: 5592.0703 | BC80: 580.0006 | BD80: 7774.4096 | BE80: 867.59187 | BF80: 2456.9546 | BG80: 6453.1873 | BH80: 7361.4426 | BI80: 10937.472 | BJ80: 2406.1138 | BK80: 3950.1054 | BL80: 3129.4021 | BM80: 2737.6559 | BN80: 2492.8391 | BO80: 5948.6571 | BP80: 637.79733 | BQ80: 14920.461 | BR80: 4536.5689 | BS80: 3659.9193 | BT80: 7433.0689 | BU80: 11490.934 | BV80: 1279.3587 | BW80: 10473.725 | BX80: 0 | BY80: 666298.34 | BZ80: 0 | CA80: 0 | CB80: 0 | CC80: 223389.89 | CD80: 107785.77 | CE80: 0 | CF80: 331175.66 | CG80: 997474
B81: Imp Import | C81: 76 | D81: 712.48471 | E81: 199.5759 | F81: 13.047764 | G81: 76.297227 | H81: 466.80115 | I81: 239.77884 | J81: 45.092211 | K81: 238.16234 | L81: 10.760873 | M81: 528.53165 | N81: 179.89358 | O81: 15.484262 | P81: 582.11499 | Q81: 903.7247 | R81: 373.57057 | S81: 89.304294 | T81: 245.81929 | U81: 54.472307 | V81: 155.63269 | W81: 3.9944096 | X81: 0.14928538 | Y81: 46.298515 | Z81: 853.5344 | AA81: 659.64531 | AB81: 267.98503 | AC81: 175.63799 | AD81: 1221.5685 | AE81: 203.34953 | AF81: 250.88856 | AG81: 153.88986 | AH81: 467.94078 | AI81: 1037.8875 | AJ81: 727.82478 | AK81: 1148.6944 | AL81: 2358.4851 | AM81: 941.11738 | AN81: 205.25746 | AO81: 337.80723 | AP81: 775.38843 | AQ81: 314.97887 | AR81: 51.452084 | AS81: 36.863498 | AT81: 42.842833 | AU81: 59.210497 | AV81: 1773.444 | AW81: 813.62324 | AX81: 365.11869 | AY81: 764.6132 | AZ81: 11.32522 | BA81: 28.371281 | BB81: 40.502798 | BC81: 23.078653 | BD81: 276.9793 | BE81: 6.1069491 | BF81: 23.590256 | BG81: 46.680084 | BH81: 85.295711 | BI81: 46.890031 | BJ81: 70.859998 | BK81: 71.367215 | BL81: 85.10213 | BM81: 31.274499 | BN81: 44.544242 | BO81: 239.64417 | BP81: 14.531849 | BQ81: 164.15405 | BR81: 116.15244 | BS81: 12.221295 | BT81: 240.39342 | BU81: 698.18873 | BV81: 16.167585 | BW81: 154.32497 | BX81: 0 | BY81: 23737.788 | BZ81: 0 | CA81: 0 | CB81: 0 | CC81: 11407.196 | CD81: 5430.0163 | CE81: 0 | CF81: 16837.212 | CG81: 40575
B82: ICMS Total | C82: 77 | D82: 8343.3248 | E82: 4147.5786 | F82: 444.5748 | G82: 280.50113 | H82: 2135.2467 | I82: 953.89695 | J82: 215.15108 | K82: 7586.0308 | L82: 306.04427 | M82: 6674.5662 | N82: 2477.124 | O82: 442.39621 | P82: 1237.9742 | Q82: 1774.1848 | R82: 1798.833 | S82: 1016.1477 | T82: 2030.5233 | U82: 435.32753 | V82: 8752.2784 | W82: 178.62543 | X82: 0.36781858 | Y82: 628.38128 | Z82: 2149.1884 | AA82: 1286.9069 | AB82: 1455.429 | AC82: 1781.9362 | AD82: 1993.9188 | AE82: 2222.71 | AF82: 1552.7652 | AG82: 965.71295 | AH82: 1751.693 | AI82: 2602.761 | AJ82: 1490.1682 | AK82: 1879.5987 | AL82: 2966.0638 | AM82: 1722.8801 | AN82: 883.29842 | AO82: 1714.3592 | AP82: 1225.2546 | AQ82: 12175.833 | AR82: 1988.9335 | AS82: 1424.9966 | AT82: 1656.134 | AU82: 1108.2852 | AV82: 10706.709 | AW82: 1612.3979 | AX82: 10468.138 | AY82: 8076.6371 | AZ82: 111.34152 | BA82: 2402.9494 | BB82: 783.90607 | BC82: 694.50274 | BD82: 10107.12 | BE82: 290.44062 | BF82: 399.46081 | BG82: 4518.3805 | BH82: 1004.7901 | BI82: 3115.6887 | BJ82: 907.5556 | BK82: 1600.7393 | BL82: 638.51923 | BM82: 1102.1474 | BN82: 490.89624 | BO82: 3608.0465 | BP82: 253.90625 | BQ82: 5343.4811 | BR82: 2010.6387 | BS82: 1049.8188 | BT82: 3299.4808 | BU82: 7722.846 | BV82: 443.82303 | BW82: 3537.0443 | BX82: 0 | BY82: 186159.31 | BZ82: 0 | CA82: 0 | CB82: 0 | CC82: 274756.24 | CD82: 18394.451 | CE82: 0 | CF82: 293150.69 | CG82: 479310
B83: Zeros | C83: 78 | D83: 0 | E83: 0 | F83: 0 | G83: 0 | H83: 0 | I83: 0 | J83: 0 | K83: 0 | L83: 0 | M83: 0 | N83: 0 | O83: 0 | P83: 0 | Q83: 0 | R83: 0 | S83: 0 | T83: 0 | U83: 0 | V83: 0 | W83: 0 | X83: 0 | Y83: 0 | Z83: 0 | AA83: 0 | AB83: 0 | AC83: 0 | AD83: 0 | AE83: 0 | AF83: 0 | AG83: 0 | AH83: 0 | AI83: 0 | AJ83: 0 | AK83: 0 | AL83: 0 | AM83: 0 | AN83: 0 | AO83: 0 | AP83: 0 | AQ83: 0 | AR83: 0 | AS83: 0 | AT83: 0 | AU83: 0 | AV83: 0 | AW83: 0 | AX83: 0 | AY83: 0 | AZ83: 0 | BA83: 0 | BB83: 0 | BC83: 0 | BD83: 0 | BE83: 0 | BF83: 0 | BG83: 0 | BH83: 0 | BI83: 0 | BJ83: 0 | BK83: 0 | BL83: 0 | BM83: 0 | BN83: 0 | BO83: 0 | BP83: 0 | BQ83: 0 | BR83: 0 | BS83: 0 | BT83: 0 | BU83: 0 | BV83: 0 | BW83: 0 | BX83: 0 | BY83: 0 | BZ83: 0 | CA83: 0 | CB83: 0 | CC83: 0 | CD83: 0 | CE83: 0 | CF83: 0 | CG83: 0
B84: IPI Total | C84: 79 | D84: 92.83045 | E84: 108.75609 | F84: 8.8181189 | G84: 43.901705 | H84: 149.82467 | I84: 114.79842 | J84: 21.270716 | K84: 343.65182 | L84: 12.27611 | M84: 474.52055 | N84: 656.88983 | O84: 224.92679 | P84: 64.127689 | Q84: 91.499562 | R84: 95.836041 | S84: 103.98039 | T84: 264.25549 | U84: 70.396165 | V84: 98.002876 | W84: 2.0001427 | X84: 0.0041186166 | Y84: 10.183701 | Z84: 85.352802 | AA84: 111.77922 | AB84: 205.31806 | AC84: 57.339309 | AD84: 488.98762 | AE84: 148.60719 | AF84: 123.62493 | AG84: 62.22164 | AH84: 343.11461 | AI84: 1261.8141 | AJ84: 422.20155 | AK84: 506.16003 | AL84: 1432.0627 | AM84: 488.59848 | AN84: 502.12281 | AO84: 267.14322 | AP84: 455.42621 | AQ84: 200.78386 | AR84: 32.798227 | AS84: 23.498705 | AT84: 27.310243 | AU84: 42.842027 | AV84: 1560.7762 | AW84: 461.77681 | AX84: 574.3649 | AY84: 548.46866 | AZ84: 6.291749 | BA84: 28.427618 | BB84: 34.720319 | BC84: 52.355074 | BD84: 1985.9758 | BE84: 26.799991 | BF84: 40.444089 | BG84: 47.213289 | BH84: 192.23565 | BI84: 87.152662 | BJ84: 78.291817 | BK84: 125.437 | BL84: 82.52707 | BM84: 60.613208 | BN84: 52.163486 | BO84: 368.76159 | BP84: 18.233672 | BQ84: 160.10975 | BR84: 131.36614 | BS84: 33.137338 | BT84: 133.81203 | BU84: 479.39071 | BV84: 25.764398 | BW84: 246.34988 | BX84: 0 | BY84: 17984.82 | BZ84: 0 | CA84: 0 | CB84: 0 | CC84: 27535.434 | CD84: 8464.7465 | CE84: 0 | CF84: 36000.18 | CG84: 53985
B85: Zeros | C85: 80 | D85: 0 | E85: 0 | F85: 0 | G85: 0 | H85: 0 | I85: 0 | J85: 0 | K85: 0 | L85: 0 | M85: 0 | N85: 0 | O85: 0 | P85: 0 | Q85: 0 | R85: 0 | S85: 0 | T85: 0 | U85: 0 | V85: 0 | W85: 0 | X85: 0 | Y85: 0 | Z85: 0 | AA85: 0 | AB85: 0 | AC85: 0 | AD85: 0 | AE85: 0 | AF85: 0 | AG85: 0 | AH85: 0 | AI85: 0 | AJ85: 0 | AK85: 0 | AL85: 0 | AM85: 0 | AN85: 0 | AO85: 0 | AP85: 0 | AQ85: 0 | AR85: 0 | AS85: 0 | AT85: 0 | AU85: 0 | AV85: 0 | AW85: 0 | AX85: 0 | AY85: 0 | AZ85: 0 | BA85: 0 | BB85: 0 | BC85: 0 | BD85: 0 | BE85: 0 | BF85: 0 | BG85: 0 | BH85: 0 | BI85: 0 | BJ85: 0 | BK85: 0 | BL85: 0 | BM85: 0 | BN85: 0 | BO85: 0 | BP85: 0 | BQ85: 0 | BR85: 0 | BS85: 0 | BT85: 0 | BU85: 0 | BV85: 0 | BW85: 0 | BX85: 0 | BY85: 0 | BZ85: 0 | CA85: 0 | CB85: 0 | CC85: 0 | CD85: 0 | CE85: 0 | CF85: 0 | CG85: 0
B86: Outros IIL Total | C86: 81 | D86: 6042.8387 | E86: 1976.1746 | F86: 280.58837 | G86: 542.17693 | H86: 7778.1809 | I86: 1919.654 | J86: 507.53471 | K86: 5782.6909 | L86: 1324.3403 | M86: 5357.8042 | N86: 2360.7513 | O86: 196.44201 | P86: 1196.7163 | Q86: 1126.9178 | R86: 813.60704 | S86: 614.08995 | T86: 3188.7908 | U86: 386.25785 | V86: 41050.979 | W86: 837.81029 | X86: 1.7251865 | Y86: 1189.411 | Z86: 7474.2134 | AA86: 3009.4653 | AB86: 1473.2559 | AC86: 1482.2181 | AD86: 3363.0311 | AE86: 2491.3685 | AF86: 4071.2767 | AG86: 2442.911 | AH86: 2290.4334 | AI86: 3419.2493 | AJ86: 2196.5567 | AK86: 3229.2856 | AL86: 5950.1222 | AM86: 2615.7468 | AN86: 872.25178 | AO86: 1270.2224 | AP86: 1720.7274 | AQ86: 4884.6491 | AR86: 797.91186 | AS86: 571.67407 | AT86: 664.40077 | AU86: 1439.0873 | AV86: 10882.295 | AW86: 2927.3386 | AX86: 18595.729 | AY86: 6896.9237 | AZ86: 1024.1055 | BA86: 3522.7472 | BB86: 2896.9147 | BC86: 440.49756 | BD86: 5506.2819 | BE86: 380.87397 | BF86: 1598.8234 | BG86: 4872.6352 | BH86: 2867.2902 | BI86: 16130.832 | BJ86: 3723.3741 | BK86: 3130.7843 | BL86: 1098.7025 | BM86: 2497.4509 | BN86: 903.35185 | BO86: 3371.2999 | BP86: 393.3957 | BQ86: 14569.03 | BR86: 2067.2089 | BS86: 1689.5278 | BT86: 2196.0872 | BU86: 3526.8894 | BV86: 760.87382 | BW86: 3517.7723 | BX86: 0 | BY86: 264194.58 | BZ86: 0 | CA86: 0 | CB86: 0 | CC86: 116537.24 | CD86: 38389.184 | CE86: 0 | CF86: 154926.42 | CG86: 419121
B87: Zeros | C87: 82 | D87: 0 | E87: 0 | F87: 0 | G87: 0 | H87: 0 | I87: 0 | J87: 0 | K87: 0 | L87: 0 | M87: 0 | N87: 0 | O87: 0 | P87: 0 | Q87: 0 | R87: 0 | S87: 0 | T87: 0 | U87: 0 | V87: 0 | W87: 0 | X87: 0 | Y87: 0 | Z87: 0 | AA87: 0 | AB87: 0 | AC87: 0 | AD87: 0 | AE87: 0 | AF87: 0 | AG87: 0 | AH87: 0 | AI87: 0 | AJ87: 0 | AK87: 0 | AL87: 0 | AM87: 0 | AN87: 0 | AO87: 0 | AP87: 0 | AQ87: 0 | AR87: 0 | AS87: 0 | AT87: 0 | AU87: 0 | AV87: 0 | AW87: 0 | AX87: 0 | AY87: 0 | AZ87: 0 | BA87: 0 | BB87: 0 | BC87: 0 | BD87: 0 | BE87: 0 | BF87: 0 | BG87: 0 | BH87: 0 | BI87: 0 | BJ87: 0 | BK87: 0 | BL87: 0 | BM87: 0 | BN87: 0 | BO87: 0 | BP87: 0 | BQ87: 0 | BR87: 0 | BS87: 0 | BT87: 0 | BU87: 0 | BV87: 0 | BW87: 0 | BX87: 0 | BY87: 0 | BZ87: 0 | CA87: 0 | CB87: 0 | CC87: 0 | CD87: 0 | CE87: 0 | CF87: 0 | CG87: 0
B88: CONSUMO INTERMEDIÁRIO | C88: 83 | D88: 188526 | E88: 80267 | F88: 9462 | G88: 11860 | H88: 125178 | I88: 47192 | J88: 11249 | K88: 246575 | L88: 43131 | M88: 258915 | N88: 56464 | O88: 12112 | P88: 38746 | Q88: 38028 | R88: 28278 | S88: 20928 | T88: 77815 | U88: 11073 | V88: 392642.86 | W88: 9333.4371 | X88: 3188.7001 | Y88: 43113 | Z88: 152810 | AA88: 73056 | AB88: 39256 | AC88: 41455 | AD88: 91572 | AE88: 59131 | AF88: 115888 | AG88: 57302 | AH88: 68611 | AI88: 87944 | AJ88: 59911 | AK88: 91770 | AL88: 164702 | AM88: 75926 | AN88: 31134 | AO88: 42507 | AP88: 51453 | AQ88: 154436.32 | AR88: 22531.896 | AS88: 7774.2588 | AT88: 17302.527 | AU88: 31881 | AV88: 308793 | AW88: 77215 | AX88: 435410 | AY88: =SUM(AY79:AY87) -> 233598 | AZ88: 12967 | BA88: 34853 | BB88: 59424 | BC88: 12965 | BD88: 146427 | BE88: 9291 | BF88: 26886 | BG88: 96935 | BH88: 56861 | BI88: 226347 | BJ88: 51716 | BK88: 71738 | BL88: 23892 | BM88: 66006 | BN88: 18328 | BO88: 85056 | BP88: 7981 | BQ88: 242741 | BR88: 55962 | BS88: 40553 | BT88: 68487 | BU88: 133095 | BV88: 17382 | BW88: 85520 | BX88: 0 | BY88: 5998860 | BZ88: 1025056 | CA88: 1393480 | CB88: 102253 | CC88: 4423548 | CD88: 1057409 | CE88: -131 | CF88: 8001615 | CG88: 14000475
A89: R10 | B89: Remunerações | C89: 84 | D89: 34356 | E89: 22217 | F89: 2255 | G89: 4126 | H89: 16917 | I89: 4502 | J89: 2607 | K89: 30117 | L89: 8690 | M89: 35422 | N89: 9953 | O89: 1711 | P89: 11262 | Q89: 18543 | R89: 11048 | S89: 6644 | T89: 14028 | U89: 5664 | V89: 8644.8181 | W89: 222.3 | X89: 24.88187 | Y89: 7013 | Z89: 12903 | AA89: 9380 | AB89: 6854 | AC89: 12695 | AD89: 22917 | AE89: 19150 | AF89: 13401 | AG89: 6247 | AH89: 22042 | AI89: 9775 | AJ89: 14631 | AK89: 27620 | AL89: 20483 | AM89: 20855 | AN89: 8257 | AO89: 16648 | AP89: 13057 | AQ89: 14489.444 | AR89: 1691.8722 | AS89: 1627.8645 | AT89: 3685.8193 | AU89: 22993 | AV89: 104570 | AW89: 49181 | AX89: 352528 | AY89: =AY90+AY91+AY94 -> 87877 | AZ89: 5137 | BA89: 7492 | BB89: 44037 | BC89: 11307 | BD89: 60116 | BE89: 6798 | BF89: 11678 | BG89: 19212 | BH89: 57187 | BI89: 165217 | BJ89: 7923 | BK89: 61939 | BL89: 18585 | BM89: 15429 | BN89: 11344 | BO89: 118404 | BP89: 31074 | BQ89: 528703 | BR89: 282090 | BS89: 89933 | BT89: 127700 | BU89: 89831 | BV89: 13265 | BW89: 45395 | BX89: 74451 | BY89: 3055773 | BZ89: 0 | CA89: 0 | CB89: 0 | CC89: 0 | CD89: 0 | CE89: 0 | CF89: 0 | CG89: 3055773
A90: R11 | B90: Salários | C90: 85 | D90: 29230 | E90: 19506 | F90: 1981 | G90: 3307 | H90: 12359 | I90: 3581 | J90: 2011 | K90: 23432 | L90: 6252 | M90: 27911 | N90: 7718 | O90: 1309 | P90: 9222 | Q90: 14743 | R90: 9151 | S90: 5395 | T90: 11059 | U90: 4600 | V90: 6069.4556 | W90: 156.075 | X90: 17.469356 | Y90: 5622 | Z90: 9758 | AA90: 7225 | AB90: 5400 | AC90: 9702 | AD90: 17824 | AE90: 15527 | AF90: 10413 | AG90: 5015 | AH90: 17453 | AI90: 7775 | AJ90: 11477 | AK90: 21904 | AL90: 15859 | AM90: 17465 | AN90: 6659 | AO90: 13658 | AP90: 10523 | AQ90: 10400.448 | AR90: 1214.4171 | AS90: 1168.4727 | AT90: 2645.6621 | AU90: 17320 | AV90: 85935 | AW90: 40106 | AX90: 279452 | AY90: 71610 | AZ90: 4217 | BA90: 6119 | BB90: 34067 | BC90: 9520 | BD90: 50603 | BE90: 5563 | BF90: 9857 | BG90: 14372 | BH90: 45370 | BI90: 127124 | BJ90: 6253 | BK90: 50719 | BL90: 14886 | BM90: 12362 | BN90: 8992 | BO90: 95075 | BP90: 24376 | BQ90: 381003 | BR90: 227721 | BS90: 74374 | BT90: 102765 | BU90: 77743 | BV90: 11518 | BW90: 38820 | BX90: 70758 | BY90: 2422298 | BZ90: 0 | CA90: 0 | CB90: 0 | CC90: 0 | CD90: 0 | CE90: 0 | CF90: 0 | CG90: 2422298
A91: R12 | B91: Contribuições sociais efetivas | C91: 86 | D91: 5126 | E91: 2711 | F91: 274 | G91: 819 | H91: 4558 | I91: 921 | J91: 596 | K91: 6685 | L91: 2438 | M91: 7511 | N91: 2235 | O91: 402 | P91: 2040 | Q91: 3800 | R91: 1897 | S91: 1249 | T91: 2969 | U91: 1064 | V91: 2575.3625 | W91: 66.225 | X91: 7.412514 | Y91: 1391 | Z91: 3145 | AA91: 2155 | AB91: 1454 | AC91: 2993 | AD91: 5093 | AE91: 3623 | AF91: 2988 | AG91: 1232 | AH91: 4589 | AI91: 2000 | AJ91: 3154 | AK91: 5716 | AL91: 4624 | AM91: 3390 | AN91: 1598 | AO91: 2990 | AP91: 2534 | AQ91: 4088.9959 | AR91: 477.45506 | AS91: 459.39176 | AT91: 1040.1573 | AU91: 5673 | AV91: 18635 | AW91: 9075 | AX91: 73076 | AY91: =AY92+AY93 -> 16267 | AZ91: 920 | BA91: 1373 | BB91: 9970 | BC91: 1787 | BD91: 9513 | BE91: 1235 | BF91: 1821 | BG91: 4840 | BH91: 11817 | BI91: 38093 | BJ91: 1670 | BK91: 11220 | BL91: 3699 | BM91: 3067 | BN91: 2352 | BO91: 23329 | BP91: 6698 | BQ91: 64857 | BR91: 47663 | BS91: 15559 | BT91: 17672 | BU91: 12088 | BV91: 1747 | BW91: 6575 | BX91: 3693 | BY91: 536663 | BZ91: 0 | CA91: 0 | CB91: 0 | CC91: 0 | CD91: 0 | CE91: 0 | CF91: 0 | CG91: 536663
B92: Previdência oficial /FGTS | C92: 87 | D92: 5123 | E92: 2698 | F92: 272 | G92: 806 | H92: 3536 | I92: 884 | J92: 566 | K92: 6513 | L92: 2394 | M92: 7273 | N92: 2148 | O92: 367 | P92: 1996 | Q92: 3739 | R92: 1856 | S92: 1182 | T92: 2686 | U92: 1025 | V92: 1824.8227 | W92: 46.925 | X92: 5.2522797 | Y92: 1350 | Z92: 2868 | AA92: 1980 | AB92: 1412 | AC92: 2814 | AD92: 4943 | AE92: 3466 | AF92: 2727 | AG92: 1168 | AH92: 4470 | AI92: 1937 | AJ92: 3036 | AK92: 5460 | AL92: 4407 | AM92: 3257 | AN92: 1477 | AO92: 2905 | AP92: 2436 | AQ92: 3142.5814 | AR92: 366.94617 | AS92: 353.06369 | AT92: 799.40869 | AU92: 5109 | AV92: 18183 | AW92: 8959 | AX92: 71753 | AY92: 15650 | AZ92: 881 | BA92: 1333 | BB92: 8842 | BC92: 1736 | BD92: 9380 | BE92: 1198 | BF92: 1745 | BG92: 3960 | BH92: 11081 | BI92: 32184 | BJ92: 1614 | BK92: 10153 | BL92: 3565 | BM92: 3015 | BN92: 2297 | BO92: 22948 | BP92: 6601 | BQ92: 64134 | BR92: 47469 | BS92: 15429 | BT92: 17649 | BU92: 11939 | BV92: 1701 | BW92: 6456 | BX92: 3693 | BY92: 514373 | BZ92: 0 | CA92: 0 | CB92: 0 | CC92: 0 | CD92: 0 | CE92: 0 | CF92: 0 | CG92: 514373
B93: Previdência privada | C93: 88 | D93: 3 | E93: 13 | F93: 2 | G93: 13 | H93: 1022 | I93: 37 | J93: 30 | K93: 172 | L93: 44 | M93: 238 | N93: 87 | O93: 35 | P93: 44 | Q93: 61 | R93: 41 | S93: 67 | T93: 283 | U93: 39 | V93: 750.53977 | W93: 19.3 | X93: 2.1602344 | Y93: 41 | Z93: 277 | AA93: 175 | AB93: 42 | AC93: 179 | AD93: 150 | AE93: 157 | AF93: 261 | AG93: 64 | AH93: 119 | AI93: 63 | AJ93: 118 | AK93: 256 | AL93: 217 | AM93: 133 | AN93: 121 | AO93: 85 | AP93: 98 | AQ93: 946.41449 | AR93: 110.50889 | AS93: 106.32806 | AT93: 240.74856 | AU93: 564 | AV93: 452 | AW93: 116 | AX93: 1323 | AY93: 617 | AZ93: 39 | BA93: 40 | BB93: 1128 | BC93: 51 | BD93: 133 | BE93: 37 | BF93: 76 | BG93: 880 | BH93: 736 | BI93: 5909 | BJ93: 56 | BK93: 1067 | BL93: 134 | BM93: 52 | BN93: 55 | BO93: 381 | BP93: 97 | BQ93: 723 | BR93: 194 | BS93: 130 | BT93: 23 | BU93: 149 | BV93: 46 | BW93: 119 | BX93: 0 | BY93: 22290 | BZ93: 0 | CA93: 0 | CB93: 0 | CC93: 0 | CD93: 0 | CE93: 0 | CF93: 0 | CG93: 22290
A94: R13 | B94: Contribuições sociais imputadas | C94: 89 | D94: 0 | E94: 0 | F94: 0 | G94: 0 | H94: 0 | I94: 0 | J94: 0 | K94: 0 | L94: 0 | M94: 0 | N94: 0 | O94: 0 | P94: 0 | Q94: 0 | R94: 0 | S94: 0 | T94: 0 | U94: 0 | V94: 0 | W94: 0 | X94: 0 | Y94: 0 | Z94: 0 | AA94: 0 | AB94: 0 | AC94: 0 | AD94: 0 | AE94: 0 | AF94: 0 | AG94: 0 | AH94: 0 | AI94: 0 | AJ94: 0 | AK94: 0 | AL94: 0 | AM94: 0 | AN94: 0 | AO94: 0 | AP94: 0 | AQ94: 0 | AR94: 0 | AS94: 0 | AT94: 0 | AU94: 0 | AV94: 0 | AW94: 0 | AX94: 0 | AY94: 0 | AZ94: 0 | BA94: 0 | BB94: 0 | BC94: 0 | BD94: 0 | BE94: 0 | BF94: 0 | BG94: 0 | BH94: 0 | BI94: 0 | BJ94: 0 | BK94: 0 | BL94: 0 | BM94: 0 | BN94: 0 | BO94: 0 | BP94: 0 | BQ94: 82843 | BR94: 6706 | BS94: 0 | BT94: 7263 | BU94: 0 | BV94: 0 | BW94: 0 | BX94: 0 | BY94: 96812 | BZ94: 0 | CA94: 0 | CB94: 0 | CC94: 0 | CD94: 0 | CE94: 0 | CF94: 0 | CG94: 96812
A95: N2 | B95: Excedente operacional bruto e rendimento misto bruto | C95: 90 | D95: 182575 | E95: 48953 | F95: 26039 | G95: 3887 | H95: 82275 | I95: 40026 | J95: 4247 | K95: 13233 | L95: -927 | M95: 27501 | N95: 11221 | O95: 1741 | P95: 4276 | Q95: 9211 | R95: 4032 | S95: 4783 | T95: 16893 | U95: 4315 | V95: 31352.535 | W95: 806.225 | X95: 90.240153 | Y95: 4134 | Z95: 12505 | AA95: 5167 | AB95: 3587 | AC95: 21406 | AD95: 5651 | AE95: 4831 | AF95: 19673 | AG95: 9072 | AH95: 10310 | AI95: 4751 | AJ95: 4693 | AK95: 8755 | AL95: 1419 | AM95: 8283 | AN95: 2054 | AO95: 15383 | AP95: 14972 | AQ95: 60670.726 | AR95: 9910.6183 | AS95: 7100.5882 | AT95: 18879.067 | AU95: 26426 | AV95: 135690 | AW95: 47260 | AX95: 320736 | AY95: =AY96+AY97 -> 75354 | AZ95: 4521 | BA95: 1775 | BB95: 33698 | BC95: 3121 | BD95: 68654 | BE95: 1586 | BF95: 3948 | BG95: 43825 | BH95: 51289 | BI95: 249222 | BJ95: 579640 | BK95: 92276 | BL95: 20171 | BM95: 22865 | BN95: 18437 | BO95: 54852 | BP95: 2998 | BQ95: 87157 | BR95: 13026 | BS95: 10137 | BT95: 6529 | BU95: 77062 | BV95: 9413 | BW95: 39805 | BX95: 0 | BY95: 2871210 | BZ95: 0 | CA95: 0 | CB95: 0 | CC95: 0 | CD95: 0 | CE95: 0 | CF95: 0 | CG95: 2871210
B96: Rendimento misto bruto | C96: 91 | D96: 97228 | E96: 38269 | F96: 12179 | G96: 254 | H96: 0 | I96: 0 | J96: 0 | K96: 365 | L96: 0 | M96: 4151 | N96: 23 | O96: 0 | P96: 1228 | Q96: 6429 | R96: 625 | S96: 1625 | T96: 296 | U96: 460 | V96: 0 | W96: 0 | X96: 0 | Y96: 0 | Z96: 0 | AA96: 0 | AB96: 585 | AC96: 0 | AD96: 373 | AE96: 799 | AF96: 0 | AG96: -18 | AH96: 2385 | AI96: 0 | AJ96: 0 | AK96: 0 | AL96: 0 | AM96: 28 | AN96: 0 | AO96: 1333 | AP96: 5023 | AQ96: 0 | AR96: 0 | AS96: 0 | AT96: 0 | AU96: 1734 | AV96: 68569 | AW96: 22740 | AX96: 58881 | AY96: 25394 | AZ96: 430 | BA96: 0 | BB96: 1273 | BC96: 1302 | BD96: 48476 | BE96: 56 | BF96: 853 | BG96: 253 | BH96: 9240 | BI96: 2638 | BJ96: 4300 | BK96: 39398 | BL96: 11034 | BM96: 6368 | BN96: 793 | BO96: 7868 | BP96: 1175 | BQ96: 0 | BR96: 0 | BS96: 7947 | BT96: 0 | BU96: 50020 | BV96: 6325 | BW96: 32861 | BX96: 0 | BY96: 583568 | BZ96: 0 | CA96: 0 | CB96: 0 | CC96: 0 | CD96: 0 | CE96: 0 | CF96: 0 | CG96: 583568
B97: Excedente operacional bruto (EOB) | C97: 92 | D97: 85347 | E97: 10684 | F97: 13860 | G97: 3633 | H97: 82275 | I97: 40026 | J97: 4247 | K97: 12868 | L97: -927 | M97: 23350 | N97: 11198 | O97: 1741 | P97: 3048 | Q97: 2782 | R97: 3407 | S97: 3158 | T97: 16597 | U97: 3855 | V97: 31352.535 | W97: 806.225 | X97: 90.240153 | Y97: 4134 | Z97: 12505 | AA97: 5167 | AB97: 3002 | AC97: 21406 | AD97: 5278 | AE97: 4032 | AF97: 19673 | AG97: 9090 | AH97: 7925 | AI97: 4751 | AJ97: 4693 | AK97: 8755 | AL97: 1419 | AM97: 8255 | AN97: 2054 | AO97: 14050 | AP97: 9949 | AQ97: 60670.726 | AR97: 9910.6183 | AS97: 7100.5882 | AT97: 18879.067 | AU97: 24692 | AV97: 67121 | AW97: 24520 | AX97: 261855 | AY97: 49960 | AZ97: 4091 | BA97: 1775 | BB97: 32425 | BC97: 1819 | BD97: 20178 | BE97: 1530 | BF97: 3095 | BG97: 43572 | BH97: 42049 | BI97: 246584 | BJ97: 575340 | BK97: 52878 | BL97: 9137 | BM97: 16497 | BN97: 17644 | BO97: 46984 | BP97: 1823 | BQ97: 87157 | BR97: 13026 | BS97: 2190 | BT97: 6529 | BU97: 27042 | BV97: 3088 | BW97: 6944 | BX97: 0 | BY97: 2287642 | BZ97: 0 | CA97: 0 | CB97: 0 | CC97: 0 | CD97: 0 | CE97: 0 | CF97: 0 | CG97: 2287642
A98: N0 | B98: VALOR ADICIONADO CUSTO FATORES | C98: 93 | D98: 216931 | E98: 71170 | F98: 28294 | G98: 8013 | H98: 99192 | I98: 44528 | J98: 6854 | K98: 43350 | L98: 7763 | M98: 62923 | N98: 21174 | O98: 3452 | P98: 15538 | Q98: 27754 | R98: 15080 | S98: 11427 | T98: 30921 | U98: 9979 | V98: 39997.353 | W98: 1028.525 | X98: 115.12202 | Y98: 11147 | Z98: 25408 | AA98: 14547 | AB98: 10441 | AC98: 34101 | AD98: 28568 | AE98: 23981 | AF98: 33074 | AG98: 15319 | AH98: 32352 | AI98: 14526 | AJ98: 19324 | AK98: 36375 | AL98: 21902 | AM98: 29138 | AN98: 10311 | AO98: 32031 | AP98: 28029 | AQ98: 75160.17 | AR98: 11602.49 | AS98: 8728.4526 | AT98: 22564.887 | AU98: 49419 | AV98: 240260 | AW98: 96441 | AX98: 673264 | AY98: =AY95+AY89 -> 163231 | AZ98: 9658 | BA98: 9267 | BB98: 77735 | BC98: 14428 | BD98: 128770 | BE98: 8384 | BF98: 15626 | BG98: 63037 | BH98: 108476 | BI98: 414439 | BJ98: 587563 | BK98: 154215 | BL98: 38756 | BM98: 38294 | BN98: 29781 | BO98: 173256 | BP98: 34072 | BQ98: 615860 | BR98: 295116 | BS98: 100070 | BT98: 134229 | BU98: 166893 | BV98: 22678 | BW98: 85200 | BX98: 74451 | BY98: 5926983 | BZ98: 0 | CA98: 0 | CB98: 0 | CC98: 0 | CD98: 0 | CE98: 0 | CF98: 0 | CG98: 5926983
A99: R22 | B99: Outros impostos sobre a produção | C99: 94 | D99: 1841 | E99: 641 | F99: 151 | G99: 199 | H99: 1568 | I99: 630 | J99: 170 | K99: 2563 | L99: 775 | M99: 3210 | N99: 938 | O99: 130 | P99: 530 | Q99: 650 | R99: 490 | S99: 363 | T99: 939 | U99: 281 | V99: 1318.0446 | W99: 26.9 | X99: 0.055391439 | Y99: 501 | Z99: 1318 | AA99: 705 | AB99: 479 | AC99: 709 | AD99: 1197 | AE99: 875 | AF99: 1156 | AG99: 555 | AH99: 1058 | AI99: 1074 | AJ99: 784 | AK99: 1363 | AL99: 1530 | AM99: 1108 | AN99: 419 | AO99: 725 | AP99: 486 | AQ99: 2228.8841 | AR99: 364.09024 | AS99: 260.85707 | AT99: 303.16862 | AU99: 951 | AV99: 3384 | AW99: 1466 | AX99: 12523 | AY99: 3613 | AZ99: 417 | BA99: 712 | BB99: 1734 | BC99: 394 | BD99: 1741 | BE99: 228 | BF99: 1362 | BG99: 6971 | BH99: 2073 | BI99: 8223 | BJ99: 473 | BK99: 2660 | BL99: 617 | BM99: 520 | BN99: 525 | BO99: 3452 | BP99: 1043 | BQ99: 163 | BR99: 17 | BS99: 2814 | BT99: 0 | BU99: 3006 | BV99: 306 | BW99: 1199 | BX99: 0 | BY99: 99200 | BZ99: 0 | CA99: 0 | CB99: 0 | CC99: 0 | CD99: 0 | CE99: 0 | CF99: 0 | CG99: 99200
A100: R32 | B100: Outros subsídios à produção | C100: 95 | D100: -9261 | E100: -119 | F100: -37 | G100: -61 | H100: 0 | I100: -24 | J100: 0 | K100: -82 | L100: -114 | M100: -105 | N100: -32 | O100: 0 | P100: -21 | Q100: 0 | R100: 0 | S100: -31 | T100: -80 | U100: 0 | V100: -146.99382 | W100: -3 | X100: -0.006177484 | Y100: -124 | Z100: -30 | AA100: 0 | AB100: 0 | AC100: -21 | AD100: -120 | AE100: -99 | AF100: -53 | AG100: -28 | AH100: -67 | AI100: 0 | AJ100: -74 | AK100: -195 | AL100: -219 | AM100: -180 | AN100: -51 | AO100: -28 | AP100: 0 | AQ100: -84.015586 | AR100: -13.724022 | AS100: -9.8327498 | AT100: -11.427642 | AU100: -31 | AV100: -364 | AW100: -29 | AX100: -618 | AY100: -1629 | AZ100: 0 | BA100: -25 | BB100: -49 | BC100: 0 | BD100: 0 | BE100: 0 | BF100: 0 | BG100: -64 | BH100: 0 | BI100: 0 | BJ100: 0 | BK100: 0 | BL100: -374 | BM100: 0 | BN100: -155 | BO100: -49 | BP100: 0 | BQ100: 0 | BR100: 0 | BS100: 0 | BT100: 0 | BU100: -121 | BV100: 0 | BW100: 0 | BX100: 0 | BY100: -15033 | BZ100: 0 | CA100: 0 | CB100: 0 | CC100: 0 | CD100: 0 | CE100: 0 | CF100: 0 | CG100: -15033
A101: N1 | B101: Valor adicionado bruto ( PIB ) | C101: 96 | D101: 209511 | E101: 71692 | F101: 28408 | G101: 8151 | H101: 100760 | I101: 45134 | J101: 7024 | K101: 45831 | L101: 8424 | M101: 66028 | N101: 22080 | O101: 3582 | P101: 16047 | Q101: 28404 | R101: 15570 | S101: 11759 | T101: 31780 | U101: 10260 | V101: 41168.404 | W101: 1052.425 | X101: 115.17124 | Y101: 11524 | Z101: 26696 | AA101: 15252 | AB101: 10920 | AC101: 34789 | AD101: 29645 | AE101: 24757 | AF101: 34177 | AG101: 15846 | AH101: 33343 | AI101: 15600 | AJ101: 20034 | AK101: 37543 | AL101: 23213 | AM101: 30066 | AN101: 10679 | AO101: 32728 | AP101: 28515 | AQ101: 77305.039 | AR101: 11952.857 | AS101: 8979.4769 | AT101: 22856.628 | AU101: 50339 | AV101: 243280 | AW101: 97878 | AX101: 685169 | AY101: =AY98+AY99+AY100 -> 165215 | AZ101: 10075 | BA101: 9954 | BB101: 79420 | BC101: 14822 | BD101: 130511 | BE101: 8612 | BF101: 16988 | BG101: 69944 | BH101: 110549 | BI101: 422662 | BJ101: 588036 | BK101: 156875 | BL101: 38999 | BM101: 38814 | BN101: 30151 | BO101: 176659 | BP101: 35115 | BQ101: 616023 | BR101: 295133 | BS101: 102884 | BT101: 134229 | BU101: 169778 | BV101: 22984 | BW101: 86399 | BX101: 74451 | BY101: 6011150 | BZ101: 0 | CA101: 0 | CB101: 0 | CC101: 0 | CD101: 0 | CE101: 0 | CF101: 0 | CG101: 6011150
...

Sheet FM - C1
A1: (1) a matriz de fluxos em valores monetários Z, com os setores de valor adicionado e a demanda final;
A3: Valores correntes em 1 000 000 R$ | D3: S01 | E3: S02 | F3: S03 | G3: S04 | H3: S05 | I3: S06 | J3: S07 | K3: S08 | L3: S09 | M3: S10 | N3: S11 | O3: S12 | P3: S13 | Q3: S14 | R3: S15 | S3: S16 | T3: S17 | U3: S18 | V3: S19 | W3: S20 | X3: S21 | Y3: S22 | Z3: S23 | AA3: S24 | AB3: S25 | AC3: S26 | AD3: S27 | AE3: S28 | AF3: S29 | AG3: S30 | AH3: S31 | AI3: S32 | AJ3: S33 | AK3: S34 | AL3: S35 | AM3: S36 | AN3: S37 | AO3: S38 | AP3: S39 | AQ3: S40 | AR3: S41 | AS3: S42 | AT3: S43 | AU3: S44 | AV3: S45 | AW3: S46 | AX3: S47 | AY3: S48 | AZ3: S49 | BA3: S50 | BB3: S51 | BC3: S52 | BD3: S53 | BE3: S54 | BF3: S55 | BG3: S56 | BH3: S57 | BI3: S58 | BJ3: S59 | BK3: S60 | BL3: S61 | BM3: S62 | BN3: S63 | BO3: S64 | BP3: S65 | BQ3: S66 | BR3: S67 | BS3: S68 | BT3: S69 | BU3: S70 | BV3: S71 | BW3: S72 | BX3: S73
A4: Matriz de usos setor x setor | D4: Agricultura, inclusive o apoio à agricultura e a pós-colheita | E4: Pecuária, inclusive o apoio à pecuária | F4: Produção florestal; pesca e aquicultura | G4: Extração de carvão mineral e de minerais não-metálicos | H4: Extração de petróleo e gás, inclusive as atividades de apoio | I4: Extração de minério de ferro, inclusive beneficiamentos e a aglomeração | J4: Extração de minerais metálicos não-ferrosos, inclusive beneficiamentos | K4: Abate e produtos de carne, inclusive os produtos do laticínio e da pesca | L4: Fabricação e refino de açúcar | M4: Outros produtos alimentares | N4: Fabricação de bebidas | O4: Fabricação de produtos do fumo | P4: Fabricação de produtos têxteis | Q4: Confecção de artefatos do vestuário e acessórios | R4: Fabricação de calçados e de artefatos de couro | S4: Fabricação de produtos da madeira | T4: Fabricação de celulose, papel e produtos de papel | U4: Impressão e reprodução de gravações | V4: Derivados de petróleo | W4: Biodiesel | X4: Coquerias | Y4: Fabricação de biocombustíveis | Z4: Fabricação de químicos orgânicos e inorgânicos, resinas e elastômeros | AA4: Fabricação de defensivos, desinfestantes, tintas e químicos diversos | AB4: Fabricação de produtos de limpeza, cosméticos/perfumaria e higiene pessoal | AC4: Fabricação de produtos farmoquímicos e farmacêuticos | AD4: Fabricação de produtos de borracha e de material plástico | AE4: Fabricação de produtos de minerais não-metálicos | AF4: Produção de ferro-gusa/ferroligas, siderurgia e tubos de aço sem costura | AG4: Metalurgia de metais não-ferosos e a fundição de metais | AH4: Fabricação de produtos de metal, exceto máquinas e equipamentos | AI4: Fabricação de equipamentos de informática, produtos eletrônicos e ópticos | AJ4: Fabricação de máquinas e equipamentos elétricos | AK4: Fabricação de máquinas e equipamentos mecânicos | AL4: Fabricação de automóveis, caminhões e ônibus, exceto peças | AM4: Fabricação de peças e acessórios para veículos automotores | AN4: Fabricação de outros equipamentos de transporte, exceto veículos automotores | AO4: Fabricação de móveis e de produtos de indústrias diversas | AP4: Manutenção, reparação e instalação de máquinas e equipamentos | AQ4: Geração centralizada de energia elétrica | AR4: Geração distribuída de energia elétrica | AS4: Transmissão | AT4: Gás Natural | AU4: Água, esgoto e gestão de resíduos | AV4: Construção | AW4: Comércio e reparação de veículos automotores e motocicletas | AX4: Comércio por atacado e a varejo, exceto veículos automotores | AY4: Transporte terrestre | AZ4: Transporte aquaviário | BA4: Transporte aéreo | BB4: Armazenamento, atividades auxiliares dos transportes e correio | BC4: Alojamento | BD4: Alimentação | BE4: Edição e edição integrada à impressão | BF4: Atividades de televisão, rádio, cinema e gravação/edição de som e imagem | BG4: Telecomunicações | BH4: Desenvolvimento de sistemas e outros serviços de informação | BI4: Intermediação financeira, seguros e previdência complementar | BJ4: Atividades imobiliárias | BK4: Atividades jurídicas, contábeis, consultoria e sedes de empresas | BL4: Serviços de arquitetura, engenharia, testes/análises técnicas e P & D | BM4: Outras atividades profissionais, científicas e técnicas | BN4: Aluguéis não-imobiliários e gestão de ativos de propriedade intelectual | BO4: Outras atividades administrativas e serviços complementares | BP4: Atividades de vigilância, segurança e investigação | BQ4: Administração pública, defesa e seguridade social | BR4: Educação pública | BS4: Educação privada | BT4: Saúde pública | BU4: Saúde privada | BV4: Atividades artísticas, criativas e de espetáculos | BW4: Organizações associativas e outros serviços pessoais | BX4: Serviços domésticos | BY4: Consumo Intermediário total | BZ4: Exportação de bens e serviços | CA4: Consumo do governo | CB4: Consumo das ISFLSF | CC4: Consumo das famílias | CD4: Formação bruta de capital fixo | CE4: Variação de estoque | CF4: Demanda final | CG4: Demanda total | CI4: Proporção Demanda Final / Demanda total
B5: Número identificador | C5: 0 | D5: 1 | E5: 2 | F5: 3 | G5: 4 | H5: 5 | I5: 6 | J5: 7 | K5: 8 | L5: 9 | M5: 10 | N5: 11 | O5: 12 | P5: 13 | Q5: 14 | R5: 15 | S5: 16 | T5: 17 | U5: 18 | V5: 19 | W5: 20 | X5: 21 | Y5: 22 | Z5: 23 | AA5: 24 | AB5: 25 | AC5: 26 | AD5: 27 | AE5: 28 | AF5: 29 | AG5: 30 | AH5: 31 | AI5: 32 | AJ5: 33 | AK5: 34 | AL5: 35 | AM5: 36 | AN5: 37 | AO5: 38 | AP5: 39 | AQ5: 40 | AR5: 41 | AS5: 42 | AT5: 43 | AU5: 44 | AV5: 45 | AW5: 46 | AX5: 47 | AY5: 48 | AZ5: 49 | BA5: 50 | BB5: 51 | BC5: 52 | BD5: 53 | BE5: 54 | BF5: 55 | BG5: 56 | BH5: 57 | BI5: 58 | BJ5: 59 | BK5: 60 | BL5: 61 | BM5: 62 | BN5: 63 | BO5: 64 | BP5: 65 | BQ5: 66 | BR5: 67 | BS5: 68 | BT5: 69 | BU5: 70 | BV5: 71 | BW5: 72 | BX5: 73 | BY5: 74 | BZ5: 75 | CA5: 76 | CB5: 77 | CC5: 78 | CD5: 79 | CE5: 80 | CF5: 81 | CG5: 82
A6: S01 | B6: Agricultura, inclusive o apoio à agricultura e a pós-colheita | C6: 1 | D6: 8170.3586 | E6: 5290.2246 | F6: 156.75542 | G6: 1.8265937 | H6: 9.8692679 | I6: 1.1434984 | J6: 1.7841451 | K6: 7264.3074 | L6: 28021.78 | M6: 76458.432 | N6: 2089.3011 | O6: 4889.0335 | P6: 5526.2619 | Q6: 518.70182 | R6: 6.6028531 | S6: 90.994169 | T6: 172.72948 | U6: 0.25638423 | V6: 8.6760449 | W6: 0.051985351 | X6: 0.041880586 | Y6: 22484.79 | Z6: 15.129223 | AA6: 18.049511 | AB6: 2.2091675 | AC6: 13.484794 | AD6: 38.146982 | AE6: 14.418004 | AF6: 42.241869 | AG6: 26.216602 | AH6: 2.7665426 | AI6: 0.27528051 | AJ6: 0.30007581 | AK6: 0.76078595 | AL6: 0.62121565 | AM6: 0.40229091 | AN6: 0.52416479 | AO6: 10.45024 | AP6: 0.065167124 | AQ6: 0.47598929 | AR6: 0.077753282 | AS6: 0.055707325 | AT6: 0.062671933 | AU6: 28.709259 | AV6: 402.52785 | AW6: 2.6558165 | AX6: 12090.688 | AY6: 0.96387781 | AZ6: 0.028456625 | BA6: 0.29297865 | BB6: 12.456639 | BC6: 277.13534 | BD6: 4385.9634 | BE6: 0.088943908 | BF6: 0.61952657 | BG6: 44.855835 | BH6: 2.1532612 | BI6: 14.762971 | BJ6: 20.40651 | BK6: 7.4743084 | BL6: 12.024632 | BM6: 0.80278958 | BN6: 0.68757086 | BO6: 133.6114 | BP6: 0.22205855 | BQ6: 947.57032 | BR6: 357.35736 | BS6: 43.808221 | BT6: 354.48805 | BU6: 180.63426 | BV6: 2.8571215 | BW6: 249.91177 | BX6: 0 | BY6: 180926.42 | BZ6: 150718.72 | CA6: 48.304678 | CB6: 0 | CC6: 71191.699 | CD6: 3188.2578 | CE6: -8036.3973 | CF6: 217110.58 | CG6: 398037 | CI6: =CF6/CG6 -> 0.54545327
